Workbook

Sheet Пшеница мягкая 28 сен
A1: Отчет по изучению качества МЯГКОЙ ПШЕНИЦЫ нового урожая 2026 года
A2: по состоянию на 28 сентября
A4: Наименование субъекта Российской Федерации | B4: Валовой сбор, тыс.т | C4: 1 класс | E4: 2 класс | G4: 3 класс | I4: 4 класс | K4: ИТОГО 1-4 класс | M4: 5 класс | O4: несоответствующая ГОСТ
C5: тыс.т | D5: % от обслед. | E5: тыс.т | F5: % от обслед. | G5: тыс.т | H5: % от обслед. | I5: тыс.т | J5: % от обслед. | K5: тыс.т | L5: % от обслед. | M5: тыс.т | N5: % от обслед. | O5: тыс.т | P5: % от обслед.
A6: Всего | B6: 81496.587 | C6: 3.530524 | D6: 0.0056904736 | E6: 11.861475 | F6: 0.019118241 | G6: 19899.83 | H6: 32.074406 | I6: 28718.995 | J6: 46.289072 | K6: 48634.217 | L6: 78.388286 | M6: 13183.005 | N6: 21.248274 | O6: 225.48788 | P6: 0.36343976
A7: Южный фед. округ | B7: 29011.153 | G7: 8188.559 | H7: 31.985835 | I7: 12507.701 | J7: 48.857104 | K7: 20696.26 | L7: 80.842939 | M7: 4902.5375 | N7: 19.150104 | O7: 1.781 | P7: 0.0069568739
A8: Астраханская область | B8: 12.322 | G8: 1.2475 | H8: 22.306661 | I8: 2.595 | J8: 46.40143 | K8: 3.8425 | L8: 68.708091 | M8: 1.75 | N8: 31.291909
A9: Волгоградская область | B9: 4945.42 | C9: 0 | D9: 0 | E9: 0 | F9: 0 | G9: 1615.248 | H9: 35.73847 | I9: 2101.9958 | J9: 46.5081 | K9: 3717.2438 | L9: 82.246571 | M9: 802.39 | N9: 17.753429 | O9: 0 | P9: 0
A10: Ростовская область | B10: 12137.351 | C10: 0 | D10: 0 | E10: 0 | F10: 0 | G10: 3901.785 | H10: 35.703035 | I10: 5118.6583 | J10: 46.837957 | K10: 9020.4433 | L10: 82.540992 | M10: 1907.9973 | N10: 17.459008 | O10: 0 | P10: 0
A11: г. Севастополь | B11: 0.656 | K11: 0 | L11: 0 | M11: 0.5164 | N11: 100
A12: Республика Крым | B12: 1089.0889 | G12: 149.28045 | H12: 19.372617 | I12: 311.88628 | J12: 40.474514 | K12: 461.16673 | L12: 59.84713 | M12: 307.62678 | N12: 39.921743 | O12: 1.781 | P12: 0.23112626
A13: Республика Адыгея | B13: 380.297 | C13: 0 | D13: 0 | E13: 0 | F13: 0 | G13: 18.846 | H13: 6.3616478 | I13: 162.279 | J13: 54.778831 | K13: 181.125 | L13: 61.140479 | M13: 115.119 | N13: 38.859521 | O13: 0 | P13: 0
A14: Республика Калмыкия | B14: 924.61971 | C14: 0 | D14: 0 | E14: 0 | F14: 0 | G14: 184.5891 | H14: 29.100446 | I14: 206.77992 | J14: 32.598825 | K14: 391.36902 | L14: 61.69927 | M14: 242.94808 | N14: 38.30073 | O14: 0 | P14: 0
A15: Краснодарский край | B15: 9521.399 | C15: 0 | D15: 0 | E15: 0 | F15: 0 | G15: 2317.563 | H15: 27.442174 | I15: 4603.5071 | J15: 54.509951 | K15: 6921.0701 | L15: 81.952125 | M15: 1524.19 | N15: 18.047875 | O15: 0 | P15: 0
A16: Приволжский фед. округ | B16: 14391.662 | E16: 1.04416 | F16: 0.011376911 | G16: 2729.0893 | H16: 29.735486 | I16: 3718.2535 | J16: 40.513176 | K16: 6448.387 | L16: 70.26004 | M16: 2662.0515 | N16: 29.005059 | O16: 67.448389 | P16: 0.73490107
A17: Самарская область | B17: 1861.478 | G17: 203.02945 | H17: 29.018733 | I17: 217.09703 | J17: 31.029394 | K17: 420.12648 | L17: 60.048126 | M17: 276.37401 | N17: 39.501774 | O17: 3.14912 | P17: 0.45009959
A18: Пензенская область | B18: 2080.3 | G18: 239.83 | H18: 16.071381 | I18: 812.03 | J18: 54.415391 | K18: 1051.86 | L18: 70.486772 | M18: 440.42 | N18: 29.513228
A19: Чувашская Республика | B19: 396.196 | E19: 0.21014 | F19: 0.11685452 | G19: 110.37868 | H19: 61.379308 | I19: 40.276303 | J19: 22.396822 | K19: 150.86512 | L19: 83.892984 | M19: 25.055157 | N19: 13.932656 | O19: 3.91016 | P19: 2.1743594
A20: Ульяновская область | B20: 1405.5107 | G20: 572.29698 | H20: 59.606699 | I20: 372.89538 | J20: 38.838336 | K20: 945.19237 | L20: 98.445035 | M20: 14.929561 | N20: 1.5549651
A21: Республика Татарстан | B21: 2302.46 | G21: 170.12281 | H21: 10.546795 | I21: 350.19184 | J21: 21.710209 | K21: 520.31465 | L21: 32.257004 | M21: 1043.7197 | N21: 64.705599 | O21: 48.994082 | P21: 3.0373972
A22: Республика Башкортостан | B22: 1721.9 | G22: 284.8421 | H22: 29.237304 | I22: 461.10724 | J22: 47.329846 | K22: 745.94934 | L22: 76.567149 | M22: 225.35488 | N22: 23.131304 | O22: 2.9378 | P22: 0.30154725
A23: Пермский край | B23: 109.656 | E23: 0.83402 | F23: 7.6273997 | G23: 4.901066 | H23: 44.821934 | I23: 4.92616 | J23: 45.051427 | K23: 10.661246 | L23: 97.50076 | M23: 0.27328 | N23: 2.4992396
A24: Республика Марий Эл | B24: 153.678 | G24: 26.365246 | H24: 55.981632 | I24: 19.329648 | J24: 41.042865 | K24: 45.694894 | L24: 97.024497 | M24: 1.40135 | N24: 2.9755027
A25: Республика Мордовия | B25: 878.09363 | G25: 31.300648 | H25: 4.9778924 | I25: 285.83252 | J25: 45.457318 | K25: 317.13317 | L25: 50.435211 | M25: 303.97602 | N25: 48.342766 | O25: 7.683997 | P25: 1.222023
A26: Нижегородская область | B26: 894.38984 | G26: 166.83233 | H26: 41.192101 | I26: 202.30737 | J26: 49.951143 | K26: 369.1397 | L26: 91.143244 | M26: 35.097559 | N26: 8.6658395 | O26: 0.77323 | P26: 0.19091604
A27: Оренбургская область | B27: 2588 | G27: 919.19 | H27: 42.419586 | I27: 952.26 | J27: 43.945729 | K27: 1871.45 | L27: 86.365315 | M27: 295.45 | N27: 13.634685
A28: Северо-Кавказский фед. округ | B28: 8525.6237 | C28: 0 | D28: 0 | E28: 3.02 | F28: 0.042943596 | G28: 1562.6266 | H28: 22.220134 | I28: 3249.3619 | J28: 46.205061 | K28: 4815.0085 | L28: 68.468139 | M28: 2101.237 | N28: 29.879031 | O28: 116.235 | P28: 1.6528308
A29: Республика Северная Осетия - Алания | B29: 144.432 | E29: 1.22 | F29: 0.87719298 | G29: 95.68 | H29: 68.794938 | I29: 12.14 | J29: 8.7287892 | K29: 109.04 | L29: 78.40092 | M29: 1.48 | N29: 1.0641357 | O29: 28.56 | P29: 20.534944
A30: Республика Ингушетия | B30: 50.072 | G30: 15.89 | H30: 35.299345 | I30: 18 | J30: 39.986671 | K30: 33.89 | L30: 75.286016 | O30: 11.125 | P30: 24.713984
A31: Чеченская Республика | B31: 304.56 | G31: 169.57 | H31: 63.459451 | I31: 35.27 | J31: 13.199356 | K31: 204.84 | L31: 76.658808 | M31: 1.2 | N31: 0.44908499 | O31: 61.17 | P31: 22.892107
A32: Карачаево-Черкесская Республика | B32: 80 | G32: 39.282124 | H32: 60.284134 | I32: 24.327305 | J32: 37.333789 | K32: 63.609429 | L32: 97.617923 | M32: 1.5522 | N32: 2.3820767
A33: Республика Дагестан | B33: 150.018 | G33: 19.553 | H33: 54.084032 | I33: 12.43 | J33: 34.381656 | K33: 31.983 | L33: 88.465687 | M33: 4.17 | N33: 11.534313
A34: Кабардино-Балкарская Республика | B34: 205.4 | E34: 1.8 | F34: 1.8711991 | G34: 63.62 | H34: 66.136494 | I34: 10.365 | J34: 10.774988 | K34: 75.785 | L34: 78.782681 | M34: 5.03 | N34: 5.228962 | O34: 15.38 | P34: 15.988357
A35: Ставропольский край | B35: 7591.1417 | C35: 0 | D35: 0 | E35: 0 | F35: 0 | G35: 1159.0315 | H35: 18.156205 | I35: 3136.8296 | J35: 49.138374 | K35: 4295.8611 | L35: 67.294579 | M35: 2087.8048 | N35: 32.705421 | O35: 0 | P35: 0
A36: Центральный фед. округ | B36: 20137.029 | C36: 0 | D36: 0 | E36: 1.77467 | F36: 0.011852947 | G36: 4312.0383 | H36: 28.799925 | I36: 7701.8291 | J36: 51.440197 | K36: 12015.642 | L36: 80.251975 | M36: 2938.7706 | N36: 19.627927 | O36: 17.981575 | P36: 0.12009819
A37: Белгородская область | B37: 2115.9121 | G37: 472.55184 | H37: 28.713858 | I37: 700.5957 | J37: 42.57058 | K37: 1173.1475 | L37: 71.284438 | M37: 472.57988 | N37: 28.715562
A38: Курская область | B38: 2405.218 | G38: 504.48341 | H38: 25.344701 | I38: 1046.9844 | J38: 52.599365 | K38: 1551.4678 | L38: 77.944066 | M38: 439.02087 | N38: 22.055934
A39: Ивановская область | B39: 58.262 | G39: 3.6885 | H39: 17.775724 | I39: 7.5273 | J39: 36.275777 | K39: 11.2158 | L39: 54.051501 | M39: 9.53441 | N39: 45.948499
A40: Липецкая область | B40: 2500.2 | E40: 1.77467 | F40: 0.091432945 | G40: 515.65518 | H40: 26.567121 | I40: 1020.2372 | J40: 52.563741 | K40: 1537.6671 | L40: 79.222294 | M40: 403.28539 | N40: 20.777706
A41: Воронежская область | B41: 3702.8 | C41: 0 | D41: 0 | E41: 0 | F41: 0 | G41: 821.38653 | H41: 26.717292 | I41: 1449.582 | J41: 47.150646 | K41: 2270.9686 | L41: 73.867938 | M41: 793.22586 | N41: 25.801308 | O41: 10.168596 | P41: 0.33075456
...

Sheet цвет (стрелочки)
A1: Отчет по изучению качества мягкой пшеницы нового урожая 2022 года
A2: ='Пшеница мягкая 28 сен'!A2:P2 -> по состоянию на 28 сентября
A4: Наименование субъекта Российской федерации | B4: 1 класс | D4: 2 класс | F4: 3 класс | H4: 4 класс | J4: ИТОГО 1-4 класс | L4: 5 класс | N4: несоответствующая ГОСТ
B5: ∆ к 2021 | C5: доля, % | D5: ∆ к 2021 | E5: доля, % | F5: ∆ к 2021 | G5: доля, % | H5: ∆ к 2021 | I5: доля, % | J5: ∆ к 2021 | K5: доля, % | L5: ∆ к 2021 | M5: доля, % | N5: ∆ к 2021 | O5: доля, %
A6: ='Пшеница мягкая 28 сен'!A6 -> Всего | B6: =IF('Пшеница мягкая 28 сен'!D6="","",'Пшеница мягкая 28 сен'!D6-'Пшеница мягкая 28 сен'!#REF!) -> #REF! | C6: ='Пшеница мягкая 28 сен'!D6 -> 0.0056904736 | D6: =IF('Пшеница мягкая 28 сен'!F6="","",'Пшеница мягкая 28 сен'!F6-'Пшеница мягкая 28 сен'!#REF!) -> #REF! | E6: ='Пшеница мягкая 28 сен'!F6 -> 0.019118241 | F6: =IF('Пшеница мягкая 28 сен'!H6=0,"",'Пшеница мягкая 28 сен'!H6-'Пшеница мягкая 28 сен'!#REF!) -> #REF! | G6: ='Пшеница мягкая 28 сен'!H6 -> 32.074406 | H6: =IF('Пшеница мягкая 28 сен'!J6=0,"",'Пшеница мягкая 28 сен'!J6-'Пшеница мягкая 28 сен'!#REF!) -> #REF! | I6: ='Пшеница мягкая 28 сен'!J6 -> 46.289072 | J6: =IF('Пшеница мягкая 28 сен'!L6=0,"",'Пшеница мягкая 28 сен'!L6-'Пшеница мягкая 28 сен'!#REF!) -> #REF! | K6: ='Пшеница мягкая 28 сен'!L6 -> 78.388286 | L6: =IF('Пшеница мягкая 28 сен'!N6=0,"",'Пшеница мягкая 28 сен'!N6-'Пшеница мягкая 28 сен'!#REF!) -> #REF! | M6: ='Пшеница мягкая 28 сен'!N6 -> 21.248274 | N6: =IF(OR('Пшеница мягкая 28 сен'!P6="",'Пшеница мягкая 28 сен'!P6=0),"",'Пшеница мягкая 28 сен'!P6-'Пшеница мягкая 28 сен'!#REF!) -> #REF! | O6: ='Пшеница мягкая 28 сен'!P6 -> 0.36343976
A7: ='Пшеница мягкая 28 сен'!A7 -> Южный фед. округ | B7: =IF('Пшеница мягкая 28 сен'!D7="","",'Пшеница мягкая 28 сен'!D7-'Пшеница мягкая 28 сен'!#REF!) | C7: ='Пшеница мягкая 28 сен'!D7 -> 0 | D7: =IF('Пшеница мягкая 28 сен'!F7="","",'Пшеница мягкая 28 сен'!F7-'Пшеница мягкая 28 сен'!#REF!) | E7: ='Пшеница мягкая 28 сен'!F7 -> 0 | F7: =IF('Пшеница мягкая 28 сен'!H7=0,"",'Пшеница мягкая 28 сен'!H7-'Пшеница мягкая 28 сен'!#REF!) -> #REF! | G7: ='Пшеница мягкая 28 сен'!H7 -> 31.985835 | H7: =IF('Пшеница мягкая 28 сен'!J7=0,"",'Пшеница мягкая 28 сен'!J7-'Пшеница мягкая 28 сен'!#REF!) -> #REF! | I7: ='Пшеница мягкая 28 сен'!J7 -> 48.857104 | J7: =IF('Пшеница мягкая 28 сен'!L7=0,"",'Пшеница мягкая 28 сен'!L7-'Пшеница мягкая 28 сен'!#REF!) -> #REF! | K7: ='Пшеница мягкая 28 сен'!L7 -> 80.842939 | L7: =IF('Пшеница мягкая 28 сен'!N7=0,"",'Пшеница мягкая 28 сен'!N7-'Пшеница мягкая 28 сен'!#REF!) -> #REF! | M7: ='Пшеница мягкая 28 сен'!N7 -> 19.150104 | N7: =IF(OR('Пшеница мягкая 28 сен'!P7="",'Пшеница мягкая 28 сен'!P7=0),"",'Пшеница мягкая 28 сен'!P7-'Пшеница мягкая 28 сен'!#REF!) -> #REF! | O7: ='Пшеница мягкая 28 сен'!P7 -> 0.0069568739
A8: ='Пшеница мягкая 28 сен'!A8 -> Астраханская область | B8: =IF('Пшеница мягкая 28 сен'!D8="","",'Пшеница мягкая 28 сен'!D8-'Пшеница мягкая 28 сен'!#REF!) | C8: ='Пшеница мягкая 28 сен'!D8 -> 0 | D8: =IF('Пшеница мягкая 28 сен'!F8="","",'Пшеница мягкая 28 сен'!F8-'Пшеница мягкая 28 сен'!#REF!) | E8: ='Пшеница мягкая 28 сен'!F8 -> 0 | F8: =IF('Пшеница мягкая 28 сен'!H8=0,"",'Пшеница мягкая 28 сен'!H8-'Пшеница мягкая 28 сен'!#REF!) -> #REF! | G8: ='Пшеница мягкая 28 сен'!H8 -> 22.306661 | H8: =IF('Пшеница мягкая 28 сен'!J8=0,"",'Пшеница мягкая 28 сен'!J8-'Пшеница мягкая 28 сен'!#REF!) -> #REF! | I8: ='Пшеница мягкая 28 сен'!J8 -> 46.40143 | J8: =IF('Пшеница мягкая 28 сен'!L8=0,"",'Пшеница мягкая 28 сен'!L8-'Пшеница мягкая 28 сен'!#REF!) -> #REF! | K8: ='Пшеница мягкая 28 сен'!L8 -> 68.708091 | L8: =IF('Пшеница мягкая 28 сен'!N8=0,"",'Пшеница мягкая 28 сен'!N8-'Пшеница мягкая 28 сен'!#REF!) -> #REF! | M8: ='Пшеница мягкая 28 сен'!N8 -> 31.291909 | N8: =IF(OR('Пшеница мягкая 28 сен'!P8="",'Пшеница мягкая 28 сен'!P8=0),"",'Пшеница мягкая 28 сен'!P8-'Пшеница мягкая 28 сен'!#REF!) | O8: ='Пшеница мягкая 28 сен'!P8 -> 0
A9: ='Пшеница мягкая 28 сен'!A9 -> Волгоградская область | B9: =IF('Пшеница мягкая 28 сен'!D9="","",'Пшеница мягкая 28 сен'!D9-'Пшеница мягкая 28 сен'!#REF!) -> #REF! | C9: ='Пшеница мягкая 28 сен'!D9 -> 0 | D9: =IF('Пшеница мягкая 28 сен'!F9="","",'Пшеница мягкая 28 сен'!F9-'Пшеница мягкая 28 сен'!#REF!) -> #REF! | E9: ='Пшеница мягкая 28 сен'!F9 -> 0 | F9: =IF('Пшеница мягкая 28 сен'!H9=0,"",'Пшеница мягкая 28 сен'!H9-'Пшеница мягкая 28 сен'!#REF!) -> #REF! | G9: ='Пшеница мягкая 28 сен'!H9 -> 35.73847 | H9: =IF('Пшеница мягкая 28 сен'!J9=0,"",'Пшеница мягкая 28 сен'!J9-'Пшеница мягкая 28 сен'!#REF!) -> #REF! | I9: ='Пшеница мягкая 28 сен'!J9 -> 46.5081 | J9: =IF('Пшеница мягкая 28 сен'!L9=0,"",'Пшеница мягкая 28 сен'!L9-'Пшеница мягкая 28 сен'!#REF!) -> #REF! | K9: ='Пшеница мягкая 28 сен'!L9 -> 82.246571 | L9: =IF('Пшеница мягкая 28 сен'!N9=0,"",'Пшеница мягкая 28 сен'!N9-'Пшеница мягкая 28 сен'!#REF!) -> #REF! | M9: ='Пшеница мягкая 28 сен'!N9 -> 17.753429 | N9: =IF(OR('Пшеница мягкая 28 сен'!P9="",'Пшеница мягкая 28 сен'!P9=0),"",'Пшеница мягкая 28 сен'!P9-'Пшеница мягкая 28 сен'!#REF!) | O9: ='Пшеница мягкая 28 сен'!P9 -> 0
A10: ='Пшеница мягкая 28 сен'!A10 -> Ростовская область | B10: =IF('Пшеница мягкая 28 сен'!D10="","",'Пшеница мягкая 28 сен'!D10-'Пшеница мягкая 28 сен'!#REF!) -> #REF! | C10: ='Пшеница мягкая 28 сен'!D10 -> 0 | D10: =IF('Пшеница мягкая 28 сен'!F10="","",'Пшеница мягкая 28 сен'!F10-'Пшеница мягкая 28 сен'!#REF!) -> #REF! | E10: ='Пшеница мягкая 28 сен'!F10 -> 0 | F10: =IF('Пшеница мягкая 28 сен'!H10=0,"",'Пшеница мягкая 28 сен'!H10-'Пшеница мягкая 28 сен'!#REF!) -> #REF! | G10: ='Пшеница мягкая 28 сен'!H10 -> 35.703035 | H10: =IF('Пшеница мягкая 28 сен'!J10=0,"",'Пшеница мягкая 28 сен'!J10-'Пшеница мягкая 28 сен'!#REF!) -> #REF! | I10: ='Пшеница мягкая 28 сен'!J10 -> 46.837957 | J10: =IF('Пшеница мягкая 28 сен'!L10=0,"",'Пшеница мягкая 28 сен'!L10-'Пшеница мягкая 28 сен'!#REF!) -> #REF! | K10: ='Пшеница мягкая 28 сен'!L10 -> 82.540992 | L10: =IF('Пшеница мягкая 28 сен'!N10=0,"",'Пшеница мягкая 28 сен'!N10-'Пшеница мягкая 28 сен'!#REF!) -> #REF! | M10: ='Пшеница мягкая 28 сен'!N10 -> 17.459008 | N10: =IF(OR('Пшеница мягкая 28 сен'!P10="",'Пшеница мягкая 28 сен'!P10=0),"",'Пшеница мягкая 28 сен'!P10-'Пшеница мягкая 28 сен'!#REF!) | O10: ='Пшеница мягкая 28 сен'!P10 -> 0
A11: ='Пшеница мягкая 28 сен'!#REF! -> #REF! | B11: =IF('Пшеница мягкая 28 сен'!#REF!="","",'Пшеница мягкая 28 сен'!#REF!-'Пшеница мягкая 28 сен'!#REF!) -> #REF! | C11: ='Пшеница мягкая 28 сен'!#REF! -> #REF! | D11: =IF('Пшеница мягкая 28 сен'!#REF!="","",'Пшеница мягкая 28 сен'!#REF!-'Пшеница мягкая 28 сен'!#REF!) -> #REF! | E11: ='Пшеница мягкая 28 сен'!#REF! -> #REF! | F11: =IF('Пшеница мягкая 28 сен'!#REF!=0,"",'Пшеница мягкая 28 сен'!#REF!-'Пшеница мягкая 28 сен'!#REF!) -> #REF! | G11: ='Пшеница мягкая 28 сен'!#REF! -> #REF! | H11: =IF('Пшеница мягкая 28 сен'!#REF!=0,"",'Пшеница мягкая 28 сен'!#REF!-'Пшеница мягкая 28 сен'!#REF!) -> #REF! | I11: ='Пшеница мягкая 28 сен'!#REF! -> #REF! | J11: =IF('Пшеница мягкая 28 сен'!#REF!=0,"",'Пшеница мягкая 28 сен'!#REF!-'Пшеница мягкая 28 сен'!#REF!) -> #REF! | K11: ='Пшеница мягкая 28 сен'!#REF! -> #REF! | L11: =IF('Пшеница мягкая 28 сен'!#REF!=0,"",'Пшеница мягкая 28 сен'!#REF!-'Пшеница мягкая 28 сен'!#REF!) -> #REF! | M11: ='Пшеница мягкая 28 сен'!#REF! -> #REF! | N11: =IF(OR('Пшеница мягкая 28 сен'!#REF!="",'Пшеница мягкая 28 сен'!#REF!=0),"",'Пшеница мягкая 28 сен'!#REF!-'Пшеница мягкая 28 сен'!#REF!) -> #REF! | O11: ='Пшеница мягкая 28 сен'!#REF! -> #REF!
A12: ='Пшеница мягкая 28 сен'!#REF! -> #REF! | B12: =IF('Пшеница мягкая 28 сен'!#REF!="","",'Пшеница мягкая 28 сен'!#REF!-'Пшеница мягкая 28 сен'!#REF!) -> #REF! | C12: ='Пшеница мягкая 28 сен'!#REF! -> #REF! | D12: =IF('Пшеница мягкая 28 сен'!#REF!="","",'Пшеница мягкая 28 сен'!#REF!-'Пшеница мягкая 28 сен'!#REF!) -> #REF! | E12: ='Пшеница мягкая 28 сен'!#REF! -> #REF! | F12: =IF('Пшеница мягкая 28 сен'!#REF!=0,"",'Пшеница мягкая 28 сен'!#REF!-'Пшеница мягкая 28 сен'!#REF!) -> #REF! | G12: ='Пшеница мягкая 28 сен'!#REF! -> #REF! | H12: =IF('Пшеница мягкая 28 сен'!#REF!=0,"",'Пшеница мягкая 28 сен'!#REF!-'Пшеница мягкая 28 сен'!#REF!) -> #REF! | I12: ='Пшеница мягкая 28 сен'!#REF! -> #REF! | J12: =IF('Пшеница мягкая 28 сен'!#REF!=0,"",'Пшеница мягкая 28 сен'!#REF!-'Пшеница мягкая 28 сен'!#REF!) -> #REF! | K12: ='Пшеница мягкая 28 сен'!#REF! -> #REF! | L12: =IF('Пшеница мягкая 28 сен'!#REF!=0,"",'Пшеница мягкая 28 сен'!#REF!-'Пшеница мягкая 28 сен'!#REF!) -> #REF! | M12: ='Пшеница мягкая 28 сен'!#REF! -> #REF! | N12: =IF(OR('Пшеница мягкая 28 сен'!#REF!="",'Пшеница мягкая 28 сен'!#REF!=0),"",'Пшеница мягкая 28 сен'!#REF!-'Пшеница мягкая 28 сен'!#REF!) -> #REF! | O12: ='Пшеница мягкая 28 сен'!#REF! -> #REF!
A13: ='Пшеница мягкая 28 сен'!#REF! -> #REF! | B13: =IF('Пшеница мягкая 28 сен'!#REF!="","",'Пшеница мягкая 28 сен'!#REF!-'Пшеница мягкая 28 сен'!#REF!) -> #REF! | C13: ='Пшеница мягкая 28 сен'!#REF! -> #REF! | D13: =IF('Пшеница мягкая 28 сен'!#REF!="","",'Пшеница мягкая 28 сен'!#REF!-'Пшеница мягкая 28 сен'!#REF!) -> #REF! | E13: ='Пшеница мягкая 28 сен'!#REF! -> #REF! | F13: =IF('Пшеница мягкая 28 сен'!#REF!="","",'Пшеница мягкая 28 сен'!#REF!-'Пшеница мягкая 28 сен'!#REF!) -> #REF! | G13: ='Пшеница мягкая 28 сен'!#REF! -> #REF! | H13: =IF('Пшеница мягкая 28 сен'!#REF!=0,"",'Пшеница мягкая 28 сен'!#REF!-'Пшеница мягкая 28 сен'!#REF!) -> #REF! | I13: ='Пшеница мягкая 28 сен'!#REF! -> #REF! | J13: =IF('Пшеница мягкая 28 сен'!#REF!=0,"",'Пшеница мягкая 28 сен'!#REF!-'Пшеница мягкая 28 сен'!#REF!) -> #REF! | K13: ='Пшеница мягкая 28 сен'!#REF! -> #REF! | L13: =IF('Пшеница мягкая 28 сен'!#REF!=0,"",'Пшеница мягкая 28 сен'!#REF!-'Пшеница мягкая 28 сен'!#REF!) -> #REF! | M13: ='Пшеница мягкая 28 сен'!#REF! -> #REF! | N13: =IF(OR('Пшеница мягкая 28 сен'!#REF!="",'Пшеница мягкая 28 сен'!#REF!=0),"",'Пшеница мягкая 28 сен'!#REF!-'Пшеница мягкая 28 сен'!#REF!) -> #REF! | O13: ='Пшеница мягкая 28 сен'!#REF! -> #REF!
A14: ='Пшеница мягкая 28 сен'!#REF! -> #REF! | B14: =IF('Пшеница мягкая 28 сен'!#REF!="","",'Пшеница мягкая 28 сен'!#REF!-'Пшеница мягкая 28 сен'!#REF!) -> #REF! | C14: ='Пшеница мягкая 28 сен'!#REF! -> #REF! | D14: =IF('Пшеница мягкая 28 сен'!#REF!="","",'Пшеница мягкая 28 сен'!#REF!-'Пшеница мягкая 28 сен'!#REF!) -> #REF! | E14: ='Пшеница мягкая 28 сен'!#REF! -> #REF! | F14: =IF('Пшеница мягкая 28 сен'!#REF!=0,"",'Пшеница мягкая 28 сен'!#REF!-'Пшеница мягкая 28 сен'!#REF!) -> #REF! | G14: ='Пшеница мягкая 28 сен'!#REF! -> #REF! | H14: =IF('Пшеница мягкая 28 сен'!#REF!=0,"",'Пшеница мягкая 28 сен'!#REF!-'Пшеница мягкая 28 сен'!#REF!) -> #REF! | I14: ='Пшеница мягкая 28 сен'!#REF! -> #REF! | J14: =IF('Пшеница мягкая 28 сен'!#REF!=0,"",'Пшеница мягкая 28 сен'!#REF!-'Пшеница мягкая 28 сен'!#REF!) -> #REF! | K14: ='Пшеница мягкая 28 сен'!#REF! -> #REF! | L14: =IF('Пшеница мягкая 28 сен'!#REF!=0,"",'Пшеница мягкая 28 сен'!#REF!-'Пшеница мягкая 28 сен'!#REF!) -> #REF! | M14: ='Пшеница мягкая 28 сен'!#REF! -> #REF! | N14: =IF(OR('Пшеница мягкая 28 сен'!#REF!="",'Пшеница мягкая 28 сен'!#REF!=0),"",'Пшеница мягкая 28 сен'!#REF!-'Пшеница мягкая 28 сен'!#REF!) -> #REF! | O14: ='Пшеница мягкая 28 сен'!#REF! -> #REF!
A15: ='Пшеница мягкая 28 сен'!#REF! -> #REF! | B15: =IF('Пшеница мягкая 28 сен'!#REF!="","",'Пшеница мягкая 28 сен'!#REF!-'Пшеница мягкая 28 сен'!#REF!) -> #REF! | C15: ='Пшеница мягкая 28 сен'!#REF! -> #REF! | D15: =IF('Пшеница мягкая 28 сен'!#REF!="","",'Пшеница мягкая 28 сен'!#REF!-'Пшеница мягкая 28 сен'!#REF!) -> #REF! | E15: ='Пшеница мягкая 28 сен'!#REF! -> #REF! | F15: =IF('Пшеница мягкая 28 сен'!#REF!=0,"",'Пшеница мягкая 28 сен'!#REF!-'Пшеница мягкая 28 сен'!#REF!) -> #REF! | G15: ='Пшеница мягкая 28 сен'!#REF! -> #REF! | H15: =IF('Пшеница мягкая 28 сен'!#REF!=0,"",'Пшеница мягкая 28 сен'!#REF!-'Пшеница мягкая 28 сен'!#REF!) -> #REF! | I15: ='Пшеница мягкая 28 сен'!#REF! -> #REF! | J15: =IF('Пшеница мягкая 28 сен'!#REF!=0,"",'Пшеница мягкая 28 сен'!#REF!-'Пшеница мягкая 28 сен'!#REF!) -> #REF! | K15: ='Пшеница мягкая 28 сен'!#REF! -> #REF! | L15: =IF('Пшеница мягкая 28 сен'!#REF!=0,"",'Пшеница мягкая 28 сен'!#REF!-'Пшеница мягкая 28 сен'!#REF!) -> #REF! | M15: ='Пшеница мягкая 28 сен'!#REF! -> #REF! | N15: =IF(OR('Пшеница мягкая 28 сен'!#REF!="",'Пшеница мягкая 28 сен'!#REF!=0),"",'Пшеница мягкая 28 сен'!#REF!-'Пшеница мягкая 28 сен'!#REF!) -> #REF! | O15: ='Пшеница мягкая 28 сен'!#REF! -> #REF!
A16: ='Пшеница мягкая 28 сен'!#REF! -> #REF! | B16: =IF('Пшеница мягкая 28 сен'!#REF!="","",'Пшеница мягкая 28 сен'!#REF!-'Пшеница мягкая 28 сен'!#REF!) -> #REF! | C16: ='Пшеница мягкая 28 сен'!#REF! -> #REF! | D16: =IF('Пшеница мягкая 28 сен'!#REF!="","",'Пшеница мягкая 28 сен'!#REF!-'Пшеница мягкая 28 сен'!#REF!) -> #REF! | E16: ='Пшеница мягкая 28 сен'!#REF! -> #REF! | F16: =IF('Пшеница мягкая 28 сен'!#REF!=0,"",'Пшеница мягкая 28 сен'!#REF!-'Пшеница мягкая 28 сен'!#REF!) -> #REF! | G16: ='Пшеница мягкая 28 сен'!#REF! -> #REF! | H16: =IF('Пшеница мягкая 28 сен'!#REF!=0,"",'Пшеница мягкая 28 сен'!#REF!-'Пшеница мягкая 28 сен'!#REF!) -> #REF! | I16: ='Пшеница мягкая 28 сен'!#REF! -> #REF! | J16: =IF('Пшеница мягкая 28 сен'!#REF!=0,"",'Пшеница мягкая 28 сен'!#REF!-'Пшеница мягкая 28 сен'!#REF!) -> #REF! | K16: ='Пшеница мягкая 28 сен'!#REF! -> #REF! | L16: =IF('Пшеница мягкая 28 сен'!#REF!=0,"",'Пшеница мягкая 28 сен'!#REF!-'Пшеница мягкая 28 сен'!#REF!) -> #REF! | M16: ='Пшеница мягкая 28 сен'!#REF! -> #REF! | N16: =IF(OR('Пшеница мягкая 28 сен'!#REF!="",'Пшеница мягкая 28 сен'!#REF!=0),"",'Пшеница мягкая 28 сен'!#REF!-'Пшеница мягкая 28 сен'!#REF!) -> #REF! | O16: ='Пшеница мягкая 28 сен'!#REF! -> #REF!
A17: ='Пшеница мягкая 28 сен'!#REF! -> #REF! | B17: =IF('Пшеница мягкая 28 сен'!#REF!="","",'Пшеница мягкая 28 сен'!#REF!-'Пшеница мягкая 28 сен'!#REF!) -> #REF! | C17: ='Пшеница мягкая 28 сен'!#REF! -> #REF! | D17: =IF('Пшеница мягкая 28 сен'!#REF!="","",'Пшеница мягкая 28 сен'!#REF!-'Пшеница мягкая 28 сен'!#REF!) -> #REF! | E17: ='Пшеница мягкая 28 сен'!#REF! -> #REF! | F17: =IF('Пшеница мягкая 28 сен'!#REF!=0,"",'Пшеница мягкая 28 сен'!#REF!-'Пшеница мягкая 28 сен'!#REF!) -> #REF! | G17: ='Пшеница мягкая 28 сен'!#REF! -> #REF! | H17: =IF('Пшеница мягкая 28 сен'!#REF!=0,"",'Пшеница мягкая 28 сен'!#REF!-'Пшеница мягкая 28 сен'!#REF!) -> #REF! | I17: ='Пшеница мягкая 28 сен'!#REF! -> #REF! | J17: =IF('Пшеница мягкая 28 сен'!#REF!=0,"",'Пшеница мягкая 28 сен'!#REF!-'Пшеница мягкая 28 сен'!#REF!) -> #REF! | K17: ='Пшеница мягкая 28 сен'!#REF! -> #REF! | L17: =IF('Пшеница мягкая 28 сен'!#REF!=0,"",'Пшеница мягкая 28 сен'!#REF!-'Пшеница мягкая 28 сен'!#REF!) -> #REF! | M17: ='Пшеница мягкая 28 сен'!#REF! -> #REF! | N17: =IF(OR('Пшеница мягкая 28 сен'!#REF!="",'Пшеница мягкая 28 сен'!#REF!=0),"",'Пшеница мягкая 28 сен'!#REF!-'Пшеница мягкая 28 сен'!#REF!) -> #REF! | O17: ='Пшеница мягкая 28 сен'!#REF! -> #REF!
A18: ='Пшеница мягкая 28 сен'!#REF! -> #REF! | B18: =IF('Пшеница мягкая 28 сен'!#REF!="","",'Пшеница мягкая 28 сен'!#REF!-'Пшеница мягкая 28 сен'!#REF!) -> #REF! | C18: ='Пшеница мягкая 28 сен'!#REF! -> #REF! | D18: =IF('Пшеница мягкая 28 сен'!#REF!="","",'Пшеница мягкая 28 сен'!#REF!-'Пшеница мягкая 28 сен'!#REF!) -> #REF! | E18: ='Пшеница мягкая 28 сен'!#REF! -> #REF! | F18: =IF('Пшеница мягкая 28 сен'!#REF!=0,"",'Пшеница мягкая 28 сен'!#REF!-'Пшеница мягкая 28 сен'!#REF!) -> #REF! | G18: ='Пшеница мягкая 28 сен'!#REF! -> #REF! | H18: =IF('Пшеница мягкая 28 сен'!#REF!=0,"",'Пшеница мягкая 28 сен'!#REF!-'Пшеница мягкая 28 сен'!#REF!) -> #REF! | I18: ='Пшеница мягкая 28 сен'!#REF! -> #REF! | J18: =IF('Пшеница мягкая 28 сен'!#REF!=0,"",'Пшеница мягкая 28 сен'!#REF!-'Пшеница мягкая 28 сен'!#REF!) -> #REF! | K18: ='Пшеница мягкая 28 сен'!#REF! -> #REF! | L18: =IF('Пшеница мягкая 28 сен'!#REF!=0,"",'Пшеница мягкая 28 сен'!#REF!-'Пшеница мягкая 28 сен'!#REF!) -> #REF! | M18: ='Пшеница мягкая 28 сен'!#REF! -> #REF! | N18: =IF(OR('Пшеница мягкая 28 сен'!#REF!="",'Пшеница мягкая 28 сен'!#REF!=0),"",'Пшеница мягкая 28 сен'!#REF!-'Пшеница мягкая 28 сен'!#REF!) -> #REF! | O18: ='Пшеница мягкая 28 сен'!#REF! -> #REF!
A19: ='Пшеница мягкая 28 сен'!#REF! -> #REF! | B19: =IF('Пшеница мягкая 28 сен'!#REF!="","",'Пшеница мягкая 28 сен'!#REF!-'Пшеница мягкая 28 сен'!#REF!) -> #REF! | C19: ='Пшеница мягкая 28 сен'!#REF! -> #REF! | D19: =IF('Пшеница мягкая 28 сен'!#REF!="","",'Пшеница мягкая 28 сен'!#REF!-'Пшеница мягкая 28 сен'!#REF!) -> #REF! | E19: ='Пшеница мягкая 28 сен'!#REF! -> #REF! | F19: =IF('Пшеница мягкая 28 сен'!#REF!=0,"",'Пшеница мягкая 28 сен'!#REF!-'Пшеница мягкая 28 сен'!#REF!) -> #REF! | G19: ='Пшеница мягкая 28 сен'!#REF! -> #REF! | H19: =IF('Пшеница мягкая 28 сен'!#REF!=0,"",'Пшеница мягкая 28 сен'!#REF!-'Пшеница мягкая 28 сен'!#REF!) -> #REF! | I19: ='Пшеница мягкая 28 сен'!#REF! -> #REF! | J19: =IF('Пшеница мягкая 28 сен'!#REF!=0,"",'Пшеница мягкая 28 сен'!#REF!-'Пшеница мягкая 28 сен'!#REF!) -> #REF! | K19: ='Пшеница мягкая 28 сен'!#REF! -> #REF! | L19: =IF('Пшеница мягкая 28 сен'!#REF!=0,"",'Пшеница мягкая 28 сен'!#REF!-'Пшеница мягкая 28 сен'!#REF!) -> #REF! | M19: ='Пшеница мягкая 28 сен'!#REF! -> #REF! | N19: =IF(OR('Пшеница мягкая 28 сен'!#REF!="",'Пшеница мягкая 28 сен'!#REF!=0),"",'Пшеница мягкая 28 сен'!#REF!-'Пшеница мягкая 28 сен'!#REF!) -> #REF! | O19: ='Пшеница мягкая 28 сен'!#REF! -> #REF!
A20: ='Пшеница мягкая 28 сен'!#REF! -> #REF! | B20: =IF('Пшеница мягкая 28 сен'!#REF!="","",'Пшеница мягкая 28 сен'!#REF!-'Пшеница мягкая 28 сен'!#REF!) -> #REF! | C20: ='Пшеница мягкая 28 сен'!#REF! -> #REF! | D20: =IF('Пшеница мягкая 28 сен'!#REF!="","",'Пшеница мягкая 28 сен'!#REF!-'Пшеница мягкая 28 сен'!#REF!) -> #REF! | E20: ='Пшеница мягкая 28 сен'!#REF! -> #REF! | F20: =IF('Пшеница мягкая 28 сен'!#REF!=0,"",'Пшеница мягкая 28 сен'!#REF!-'Пшеница мягкая 28 сен'!#REF!) -> #REF! | G20: ='Пшеница мягкая 28 сен'!#REF! -> #REF! | H20: =IF('Пшеница мягкая 28 сен'!#REF!=0,"",'Пшеница мягкая 28 сен'!#REF!-'Пшеница мягкая 28 сен'!#REF!) -> #REF! | I20: ='Пшеница мягкая 28 сен'!#REF! -> #REF! | J20: =IF('Пшеница мягкая 28 сен'!#REF!=0,"",'Пшеница мягкая 28 сен'!#REF!-'Пшеница мягкая 28 сен'!#REF!) -> #REF! | K20: ='Пшеница мягкая 28 сен'!#REF! -> #REF! | L20: =IF('Пшеница мягкая 28 сен'!#REF!=0,"",'Пшеница мягкая 28 сен'!#REF!-'Пшеница мягкая 28 сен'!#REF!) -> #REF! | M20: ='Пшеница мягкая 28 сен'!#REF! -> #REF! | N20: =IF(OR('Пшеница мягкая 28 сен'!#REF!="",'Пшеница мягкая 28 сен'!#REF!=0),"",'Пшеница мягкая 28 сен'!#REF!-'Пшеница мягкая 28 сен'!#REF!) -> #REF! | O20: ='Пшеница мягкая 28 сен'!#REF! -> #REF!
A21: ='Пшеница мягкая 28 сен'!#REF! -> #REF! | B21: =IF('Пшеница мягкая 28 сен'!#REF!="","",'Пшеница мягкая 28 сен'!#REF!-'Пшеница мягкая 28 сен'!#REF!) -> #REF! | C21: ='Пшеница мягкая 28 сен'!#REF! -> #REF! | D21: =IF('Пшеница мягкая 28 сен'!#REF!="","",'Пшеница мягкая 28 сен'!#REF!-'Пшеница мягкая 28 сен'!#REF!) -> #REF! | E21: ='Пшеница мягкая 28 сен'!#REF! -> #REF! | F21: =IF('Пшеница мягкая 28 сен'!#REF!=0,"",'Пшеница мягкая 28 сен'!#REF!-'Пшеница мягкая 28 сен'!#REF!) -> #REF! | G21: ='Пшеница мягкая 28 сен'!#REF! -> #REF! | H21: =IF('Пшеница мягкая 28 сен'!#REF!=0,"",'Пшеница мягкая 28 сен'!#REF!-'Пшеница мягкая 28 сен'!#REF!) -> #REF! | I21: ='Пшеница мягкая 28 сен'!#REF! -> #REF! | J21: =IF('Пшеница мягкая 28 сен'!#REF!=0,"",'Пшеница мягкая 28 сен'!#REF!-'Пшеница мягкая 28 сен'!#REF!) -> #REF! | K21: ='Пшеница мягкая 28 сен'!#REF! -> #REF! | L21: =IF('Пшеница мягкая 28 сен'!#REF!=0,"",'Пшеница мягкая 28 сен'!#REF!-'Пшеница мягкая 28 сен'!#REF!) -> #REF! | M21: ='Пшеница мягкая 28 сен'!#REF! -> #REF! | N21: =IF(OR('Пшеница мягкая 28 сен'!#REF!="",'Пшеница мягкая 28 сен'!#REF!=0),"",'Пшеница мягкая 28 сен'!#REF!-'Пшеница мягкая 28 сен'!#REF!) -> #REF! | O21: ='Пшеница мягкая 28 сен'!#REF! -> #REF!
A22: ='Пшеница мягкая 28 сен'!#REF! -> #REF! | B22: =IF('Пшеница мягкая 28 сен'!#REF!="","",'Пшеница мягкая 28 сен'!#REF!-'Пшеница мягкая 28 сен'!#REF!) -> #REF! | C22: ='Пшеница мягкая 28 сен'!#REF! -> #REF! | D22: =IF('Пшеница мягкая 28 сен'!#REF!="","",'Пшеница мягкая 28 сен'!#REF!-'Пшеница мягкая 28 сен'!#REF!) -> #REF! | E22: ='Пшеница мягкая 28 сен'!#REF! -> #REF! | F22: =IF('Пшеница мягкая 28 сен'!#REF!=0,"",'Пшеница мягкая 28 сен'!#REF!-'Пшеница мягкая 28 сен'!#REF!) -> #REF! | G22: ='Пшеница мягкая 28 сен'!#REF! -> #REF! | H22: =IF('Пшеница мягкая 28 сен'!#REF!=0,"",'Пшеница мягкая 28 сен'!#REF!-'Пшеница мягкая 28 сен'!#REF!) -> #REF! | I22: ='Пшеница мягкая 28 сен'!#REF! -> #REF! | J22: =IF('Пшеница мягкая 28 сен'!#REF!=0,"",'Пшеница мягкая 28 сен'!#REF!-'Пшеница мягкая 28 сен'!#REF!) -> #REF! | K22: ='Пшеница мягкая 28 сен'!#REF! -> #REF! | L22: =IF('Пшеница мягкая 28 сен'!#REF!=0,"",'Пшеница мягкая 28 сен'!#REF!-'Пшеница мягкая 28 сен'!#REF!) -> #REF! | M22: ='Пшеница мягкая 28 сен'!#REF! -> #REF! | N22: =IF(OR('Пшеница мягкая 28 сен'!#REF!="",'Пшеница мягкая 28 сен'!#REF!=0),"",'Пшеница мягкая 28 сен'!#REF!-'Пшеница мягкая 28 сен'!#REF!) -> #REF! | O22: ='Пшеница мягкая 28 сен'!#REF! -> #REF!
A23: ='Пшеница мягкая 28 сен'!#REF! -> #REF! | B23: =IF('Пшеница мягкая 28 сен'!#REF!="","",'Пшеница мягкая 28 сен'!#REF!-'Пшеница мягкая 28 сен'!#REF!) -> #REF! | C23: ='Пшеница мягкая 28 сен'!#REF! -> #REF! | D23: =IF('Пшеница мягкая 28 сен'!#REF!="","",'Пшеница мягкая 28 сен'!#REF!-'Пшеница мягкая 28 сен'!#REF!) -> #REF! | E23: ='Пшеница мягкая 28 сен'!#REF! -> #REF! | F23: =IF('Пшеница мягкая 28 сен'!#REF!="","",'Пшеница мягкая 28 сен'!#REF!-'Пшеница мягкая 28 сен'!#REF!) -> #REF! | G23: ='Пшеница мягкая 28 сен'!#REF! -> #REF! | H23: =IF('Пшеница мягкая 28 сен'!#REF!="","",'Пшеница мягкая 28 сен'!#REF!-'Пшеница мягкая 28 сен'!#REF!) -> #REF! | I23: ='Пшеница мягкая 28 сен'!#REF! -> #REF! | J23: =IF('Пшеница мягкая 28 сен'!#REF!="","",'Пшеница мягкая 28 сен'!#REF!-'Пшеница мягкая 28 сен'!#REF!) -> #REF! | K23: ='Пшеница мягкая 28 сен'!#REF! -> #REF! | L23: =IF('Пшеница мягкая 28 сен'!#REF!=0,"",'Пшеница мягкая 28 сен'!#REF!-'Пшеница мягкая 28 сен'!#REF!) -> #REF! | M23: ='Пшеница мягкая 28 сен'!#REF! -> #REF! | N23: =IF(OR('Пшеница мягкая 28 сен'!#REF!="",'Пшеница мягкая 28 сен'!#REF!=0),"",'Пшеница мягкая 28 сен'!#REF!-'Пшеница мягкая 28 сен'!#REF!) -> #REF! | O23: ='Пшеница мягкая 28 сен'!#REF! -> #REF!
A24: ='Пшеница мягкая 28 сен'!#REF! -> #REF! | B24: =IF('Пшеница мягкая 28 сен'!#REF!="","",'Пшеница мягкая 28 сен'!#REF!-'Пшеница мягкая 28 сен'!#REF!) -> #REF! | C24: ='Пшеница мягкая 28 сен'!#REF! -> #REF! | D24: =IF('Пшеница мягкая 28 сен'!#REF!="","",'Пшеница мягкая 28 сен'!#REF!-'Пшеница мягкая 28 сен'!#REF!) -> #REF! | E24: ='Пшеница мягкая 28 сен'!#REF! -> #REF! | F24: =IF('Пшеница мягкая 28 сен'!#REF!="","",'Пшеница мягкая 28 сен'!#REF!-'Пшеница мягкая 28 сен'!#REF!) -> #REF! | G24: ='Пшеница мягкая 28 сен'!#REF! -> #REF! | H24: =IF('Пшеница мягкая 28 сен'!#REF!="","",'Пшеница мягкая 28 сен'!#REF!-'Пшеница мягкая 28 сен'!#REF!) -> #REF! | I24: ='Пшеница мягкая 28 сен'!#REF! -> #REF! | J24: =IF('Пшеница мягкая 28 сен'!#REF!="","",'Пшеница мягкая 28 сен'!#REF!-'Пшеница мягкая 28 сен'!#REF!) -> #REF! | K24: ='Пшеница мягкая 28 сен'!#REF! -> #REF! | L24: =IF('Пшеница мягкая 28 сен'!#REF!=0,"",'Пшеница мягкая 28 сен'!#REF!-'Пшеница мягкая 28 сен'!#REF!) -> #REF! | M24: ='Пшеница мягкая 28 сен'!#REF! -> #REF! | N24: =IF(OR('Пшеница мягкая 28 сен'!#REF!="",'Пшеница мягкая 28 сен'!#REF!=0),"",'Пшеница мягкая 28 сен'!#REF!-'Пшеница мягкая 28 сен'!#REF!) -> #REF! | O24: ='Пшеница мягкая 28 сен'!#REF! -> #REF!
A25: ='Пшеница мягкая 28 сен'!#REF! -> #REF! | B25: =IF('Пшеница мягкая 28 сен'!#REF!="","",'Пшеница мягкая 28 сен'!#REF!-'Пшеница мягкая 28 сен'!#REF!) -> #REF! | C25: ='Пшеница мягкая 28 сен'!#REF! -> #REF! | D25: =IF('Пшеница мягкая 28 сен'!#REF!=0,"",'Пшеница мягкая 28 сен'!#REF!-'Пшеница мягкая 28 сен'!#REF!) -> #REF! | E25: ='Пшеница мягкая 28 сен'!#REF! -> #REF! | F25: =IF('Пшеница мягкая 28 сен'!#REF!=0,"",'Пшеница мягкая 28 сен'!#REF!-'Пшеница мягкая 28 сен'!#REF!) -> #REF! | G25: ='Пшеница мягкая 28 сен'!#REF! -> #REF! | H25: =IF('Пшеница мягкая 28 сен'!#REF!=0,"",'Пшеница мягкая 28 сен'!#REF!-'Пшеница мягкая 28 сен'!#REF!) -> #REF! | I25: ='Пшеница мягкая 28 сен'!#REF! -> #REF! | J25: =IF('Пшеница мягкая 28 сен'!#REF!=0,"",'Пшеница мягкая 28 сен'!#REF!-'Пшеница мягкая 28 сен'!#REF!) -> #REF! | K25: ='Пшеница мягкая 28 сен'!#REF! -> #REF! | L25: =IF('Пшеница мягкая 28 сен'!#REF!=0,"",'Пшеница мягкая 28 сен'!#REF!-'Пшеница мягкая 28 сен'!#REF!) -> #REF! | M25: ='Пшеница мягкая 28 сен'!#REF! -> #REF! | N25: =IF(OR('Пшеница мягкая 28 сен'!#REF!="",'Пшеница мягкая 28 сен'!#REF!=0),"",'Пшеница мягкая 28 сен'!#REF!-'Пшеница мягкая 28 сен'!#REF!) -> #REF! | O25: ='Пшеница мягкая 28 сен'!#REF! -> #REF!
A26: ='Пшеница мягкая 28 сен'!#REF! -> #REF! | B26: =IF('Пшеница мягкая 28 сен'!#REF!="","",'Пшеница мягкая 28 сен'!#REF!-'Пшеница мягкая 28 сен'!#REF!) -> #REF! | C26: ='Пшеница мягкая 28 сен'!#REF! -> #REF! | D26: =IF('Пшеница мягкая 28 сен'!#REF!=0,"",'Пшеница мягкая 28 сен'!#REF!-'Пшеница мягкая 28 сен'!#REF!) -> #REF! | E26: ='Пшеница мягкая 28 сен'!#REF! -> #REF! | F26: =IF('Пшеница мягкая 28 сен'!#REF!=0,"",'Пшеница мягкая 28 сен'!#REF!-'Пшеница мягкая 28 сен'!#REF!) -> #REF! | G26: ='Пшеница мягкая 28 сен'!#REF! -> #REF! | H26: =IF('Пшеница мягкая 28 сен'!#REF!=0,"",'Пшеница мягкая 28 сен'!#REF!-'Пшеница мягкая 28 сен'!#REF!) -> #REF! | I26: ='Пшеница мягкая 28 сен'!#REF! -> #REF! | J26: =IF('Пшеница мягкая 28 сен'!#REF!=0,"",'Пшеница мягкая 28 сен'!#REF!-'Пшеница мягкая 28 сен'!#REF!) -> #REF! | K26: ='Пшеница мягкая 28 сен'!#REF! -> #REF! | L26: =IF('Пшеница мягкая 28 сен'!#REF!=0,"",'Пшеница мягкая 28 сен'!#REF!-'Пшеница мягкая 28 сен'!#REF!) -> #REF! | M26: ='Пшеница мягкая 28 сен'!#REF! -> #REF! | N26: =IF(OR('Пшеница мягкая 28 сен'!#REF!="",'Пшеница мягкая 28 сен'!#REF!=0),"",'Пшеница мягкая 28 сен'!#REF!-'Пшеница мягкая 28 сен'!#REF!) -> #REF! | O26: ='Пшеница мягкая 28 сен'!#REF! -> #REF!
A27: ='Пшеница мягкая 28 сен'!#REF! -> #REF! | B27: =IF('Пшеница мягкая 28 сен'!#REF!="","",'Пшеница мягкая 28 сен'!#REF!-'Пшеница мягкая 28 сен'!#REF!) -> #REF! | C27: ='Пшеница мягкая 28 сен'!#REF! -> #REF! | D27: =IF('Пшеница мягкая 28 сен'!#REF!=0,"",'Пшеница мягкая 28 сен'!#REF!-'Пшеница мягкая 28 сен'!#REF!) -> #REF! | E27: ='Пшеница мягкая 28 сен'!#REF! -> #REF! | F27: =IF('Пшеница мягкая 28 сен'!#REF!=0,"",'Пшеница мягкая 28 сен'!#REF!-'Пшеница мягкая 28 сен'!#REF!) -> #REF! | G27: ='Пшеница мягкая 28 сен'!#REF! -> #REF! | H27: =IF('Пшеница мягкая 28 сен'!#REF!=0,"",'Пшеница мягкая 28 сен'!#REF!-'Пшеница мягкая 28 сен'!#REF!) -> #REF! | I27: ='Пшеница мягкая 28 сен'!#REF! -> #REF! | J27: =IF('Пшеница мягкая 28 сен'!#REF!=0,"",'Пшеница мягкая 28 сен'!#REF!-'Пшеница мягкая 28 сен'!#REF!) -> #REF! | K27: ='Пшеница мягкая 28 сен'!#REF! -> #REF! | L27: =IF('Пшеница мягкая 28 сен'!#REF!=0,"",'Пшеница мягкая 28 сен'!#REF!-'Пшеница мягкая 28 сен'!#REF!) -> #REF! | M27: ='Пшеница мягкая 28 сен'!#REF! -> #REF! | N27: =IF(OR('Пшеница мягкая 28 сен'!#REF!="",'Пшеница мягкая 28 сен'!#REF!=0),"",'Пшеница мягкая 28 сен'!#REF!-'Пшеница мягкая 28 сен'!#REF!) -> #REF! | O27: ='Пшеница мягкая 28 сен'!#REF! -> #REF!
A28: ='Пшеница мягкая 28 сен'!#REF! -> #REF! | B28: =IF('Пшеница мягкая 28 сен'!#REF!="","",'Пшеница мягкая 28 сен'!#REF!-'Пшеница мягкая 28 сен'!#REF!) -> #REF! | C28: ='Пшеница мягкая 28 сен'!#REF! -> #REF! | D28: =IF('Пшеница мягкая 28 сен'!#REF!="","",'Пшеница мягкая 28 сен'!#REF!-'Пшеница мягкая 28 сен'!#REF!) -> #REF! | E28: ='Пшеница мягкая 28 сен'!#REF! -> #REF! | F28: =IF('Пшеница мягкая 28 сен'!#REF!=0,"",'Пшеница мягкая 28 сен'!#REF!-'Пшеница мягкая 28 сен'!#REF!) -> #REF! | G28: ='Пшеница мягкая 28 сен'!#REF! -> #REF! | H28: =IF('Пшеница мягкая 28 сен'!#REF!=0,"",'Пшеница мягкая 28 сен'!#REF!-'Пшеница мягкая 28 сен'!#REF!) -> #REF! | I28: ='Пшеница мягкая 28 сен'!#REF! -> #REF! | J28: =IF('Пшеница мягкая 28 сен'!#REF!=0,"",'Пшеница мягкая 28 сен'!#REF!-'Пшеница мягкая 28 сен'!#REF!) -> #REF! | K28: ='Пшеница мягкая 28 сен'!#REF! -> #REF! | L28: =IF('Пшеница мягкая 28 сен'!#REF!=0,"",'Пшеница мягкая 28 сен'!#REF!-'Пшеница мягкая 28 сен'!#REF!) -> #REF! | M28: ='Пшеница мягкая 28 сен'!#REF! -> #REF! | N28: =IF(OR('Пшеница мягкая 28 сен'!#REF!="",'Пшеница мягкая 28 сен'!#REF!=0),"",'Пшеница мягкая 28 сен'!#REF!-'Пшеница мягкая 28 сен'!#REF!) -> #REF! | O28: ='Пшеница мягкая 28 сен'!#REF! -> #REF!
A29: ='Пшеница мягкая 28 сен'!#REF! -> #REF! | B29: =IF('Пшеница мягкая 28 сен'!#REF!="","",'Пшеница мягкая 28 сен'!#REF!-'Пшеница мягкая 28 сен'!#REF!) -> #REF! | C29: ='Пшеница мягкая 28 сен'!#REF! -> #REF! | D29: =IF('Пшеница мягкая 28 сен'!#REF!="","",'Пшеница мягкая 28 сен'!#REF!-'Пшеница мягкая 28 сен'!#REF!) -> #REF! | E29: ='Пшеница мягкая 28 сен'!#REF! -> #REF! | F29: =IF('Пшеница мягкая 28 сен'!#REF!=0,"",'Пшеница мягкая 28 сен'!#REF!-'Пшеница мягкая 28 сен'!#REF!) -> #REF! | G29: ='Пшеница мягкая 28 сен'!#REF! -> #REF! | H29: =IF('Пшеница мягкая 28 сен'!#REF!=0,"",'Пшеница мягкая 28 сен'!#REF!-'Пшеница мягкая 28 сен'!#REF!) -> #REF! | I29: ='Пшеница мягкая 28 сен'!#REF! -> #REF! | J29: =IF('Пшеница мягкая 28 сен'!#REF!=0,"",'Пшеница мягкая 28 сен'!#REF!-'Пшеница мягкая 28 сен'!#REF!) -> #REF! | K29: ='Пшеница мягкая 28 сен'!#REF! -> #REF! | L29: =IF('Пшеница мягкая 28 сен'!#REF!="","",'Пшеница мягкая 28 сен'!#REF!-'Пшеница мягкая 28 сен'!#REF!) -> #REF! | M29: ='Пшеница мягкая 28 сен'!#REF! -> #REF! | N29: =IF(OR('Пшеница мягкая 28 сен'!#REF!="",'Пшеница мягкая 28 сен'!#REF!=0),"",'Пшеница мягкая 28 сен'!#REF!-'Пшеница мягкая 28 сен'!#REF!) -> #REF! | O29: ='Пшеница мягкая 28 сен'!#REF! -> #REF!
A30: ='Пшеница мягкая 28 сен'!#REF! -> #REF! | B30: =IF('Пшеница мягкая 28 сен'!#REF!="","",'Пшеница мягкая 28 сен'!#REF!-'Пшеница мягкая 28 сен'!#REF!) -> #REF! | C30: ='Пшеница мягкая 28 сен'!#REF! -> #REF! | D30: =IF('Пшеница мягкая 28 сен'!#REF!="","",'Пшеница мягкая 28 сен'!#REF!-'Пшеница мягкая 28 сен'!#REF!) -> #REF! | E30: ='Пшеница мягкая 28 сен'!#REF! -> #REF! | F30: =IF('Пшеница мягкая 28 сен'!#REF!=0,"",'Пшеница мягкая 28 сен'!#REF!-'Пшеница мягкая 28 сен'!#REF!) -> #REF! | G30: ='Пшеница мягкая 28 сен'!#REF! -> #REF! | H30: =IF('Пшеница мягкая 28 сен'!#REF!=0,"",'Пшеница мягкая 28 сен'!#REF!-'Пшеница мягкая 28 сен'!#REF!) -> #REF! | I30: ='Пшеница мягкая 28 сен'!#REF! -> #REF! | J30: =IF('Пшеница мягкая 28 сен'!#REF!=0,"",'Пшеница мягкая 28 сен'!#REF!-'Пшеница мягкая 28 сен'!#REF!) -> #REF! | K30: ='Пшеница мягкая 28 сен'!#REF! -> #REF! | L30: =IF('Пшеница мягкая 28 сен'!#REF!=0,"",'Пшеница мягкая 28 сен'!#REF!-'Пшеница мягкая 28 сен'!#REF!) -> #REF! | M30: ='Пшеница мягкая 28 сен'!#REF! -> #REF! | N30: =IF(OR('Пшеница мягкая 28 сен'!#REF!="",'Пшеница мягкая 28 сен'!#REF!=0),"",'Пшеница мягкая 28 сен'!#REF!-'Пшеница мягкая 28 сен'!#REF!) -> #REF! | O30: ='Пшеница мягкая 28 сен'!#REF! -> #REF!
A31: ='Пшеница мягкая 28 сен'!#REF! -> #REF! | B31: =IF('Пшеница мягкая 28 сен'!#REF!="","",'Пшеница мягкая 28 сен'!#REF!-'Пшеница мягкая 28 сен'!#REF!) -> #REF! | C31: ='Пшеница мягкая 28 сен'!#REF! -> #REF! | D31: =IF('Пшеница мягкая 28 сен'!#REF!="","",'Пшеница мягкая 28 сен'!#REF!-'Пшеница мягкая 28 сен'!#REF!) -> #REF! | E31: ='Пшеница мягкая 28 сен'!#REF! -> #REF! | F31: =IF('Пшеница мягкая 28 сен'!#REF!=0,"",'Пшеница мягкая 28 сен'!#REF!-'Пшеница мягкая 28 сен'!#REF!) -> #REF! | G31: ='Пшеница мягкая 28 сен'!#REF! -> #REF! | H31: =IF('Пшеница мягкая 28 сен'!#REF!=0,"",'Пшеница мягкая 28 сен'!#REF!-'Пшеница мягкая 28 сен'!#REF!) -> #REF! | I31: ='Пшеница мягкая 28 сен'!#REF! -> #REF! | J31: =IF('Пшеница мягкая 28 сен'!#REF!=0,"",'Пшеница мягкая 28 сен'!#REF!-'Пшеница мягкая 28 сен'!#REF!) -> #REF! | K31: ='Пшеница мягкая 28 сен'!#REF! -> #REF! | L31: =IF('Пшеница мягкая 28 сен'!#REF!=0,"",'Пшеница мягкая 28 сен'!#REF!-'Пшеница мягкая 28 сен'!#REF!) -> #REF! | M31: ='Пшеница мягкая 28 сен'!#REF! -> #REF! | N31: =IF(OR('Пшеница мягкая 28 сен'!#REF!="",'Пшеница мягкая 28 сен'!#REF!=0),"",'Пшеница мягкая 28 сен'!#REF!-'Пшеница мягкая 28 сен'!#REF!) -> #REF! | O31: ='Пшеница мягкая 28 сен'!#REF! -> #REF!
A32: ='Пшеница мягкая 28 сен'!#REF! -> #REF! | B32: =IF('Пшеница мягкая 28 сен'!#REF!="","",'Пшеница мягкая 28 сен'!#REF!-'Пшеница мягкая 28 сен'!#REF!) -> #REF! | C32: ='Пшеница мягкая 28 сен'!#REF! -> #REF! | D32: =IF('Пшеница мягкая 28 сен'!#REF!="","",'Пшеница мягкая 28 сен'!#REF!-'Пшеница мягкая 28 сен'!#REF!) -> #REF! | E32: ='Пшеница мягкая 28 сен'!#REF! -> #REF! | F32: =IF('Пшеница мягкая 28 сен'!#REF!=0,"",'Пшеница мягкая 28 сен'!#REF!-'Пшеница мягкая 28 сен'!#REF!) -> #REF! | G32: ='Пшеница мягкая 28 сен'!#REF! -> #REF! | H32: =IF('Пшеница мягкая 28 сен'!#REF!=0,"",'Пшеница мягкая 28 сен'!#REF!-'Пшеница мягкая 28 сен'!#REF!) -> #REF! | I32: ='Пшеница мягкая 28 сен'!#REF! -> #REF! | J32: =IF('Пшеница мягкая 28 сен'!#REF!=0,"",'Пшеница мягкая 28 сен'!#REF!-'Пшеница мягкая 28 сен'!#REF!) -> #REF! | K32: ='Пшеница мягкая 28 сен'!#REF! -> #REF! | L32: =IF('Пшеница мягкая 28 сен'!#REF!="","",'Пшеница мягкая 28 сен'!#REF!-'Пшеница мягкая 28 сен'!#REF!) -> #REF! | M32: ='Пшеница мягкая 28 сен'!#REF! -> #REF! | N32: =IF(OR('Пшеница мягкая 28 сен'!#REF!="",'Пшеница мягкая 28 сен'!#REF!=0),"",'Пшеница мягкая 28 сен'!#REF!-'Пшеница мягкая 28 сен'!#REF!) -> #REF! | O32: ='Пшеница мягкая 28 сен'!#REF! -> #REF!
A33: ='Пшеница мягкая 28 сен'!#REF! -> #REF! | B33: =IF('Пшеница мягкая 28 сен'!#REF!="","",'Пшеница мягкая 28 сен'!#REF!-'Пшеница мягкая 28 сен'!#REF!) -> #REF! | C33: ='Пшеница мягкая 28 сен'!#REF! -> #REF! | D33: =IF('Пшеница мягкая 28 сен'!#REF!="","",'Пшеница мягкая 28 сен'!#REF!-'Пшеница мягкая 28 сен'!#REF!) -> #REF! | E33: ='Пшеница мягкая 28 сен'!#REF! -> #REF! | F33: =IF('Пшеница мягкая 28 сен'!#REF!=0,"",'Пшеница мягкая 28 сен'!#REF!-'Пшеница мягкая 28 сен'!#REF!) -> #REF! | G33: ='Пшеница мягкая 28 сен'!#REF! -> #REF! | H33: =IF('Пшеница мягкая 28 сен'!#REF!=0,"",'Пшеница мягкая 28 сен'!#REF!-'Пшеница мягкая 28 сен'!#REF!) -> #REF! | I33: ='Пшеница мягкая 28 сен'!#REF! -> #REF! | J33: =IF('Пшеница мягкая 28 сен'!#REF!=0,"",'Пшеница мягкая 28 сен'!#REF!-'Пшеница мягкая 28 сен'!#REF!) -> #REF! | K33: ='Пшеница мягкая 28 сен'!#REF! -> #REF! | L33: =IF('Пшеница мягкая 28 сен'!#REF!=0,"",'Пшеница мягкая 28 сен'!#REF!-'Пшеница мягкая 28 сен'!#REF!) -> #REF! | M33: ='Пшеница мягкая 28 сен'!#REF! -> #REF! | N33: =IF(OR('Пшеница мягкая 28 сен'!#REF!="",'Пшеница мягкая 28 сен'!#REF!=0),"",'Пшеница мягкая 28 сен'!#REF!-'Пшеница мягкая 28 сен'!#REF!) -> #REF! | O33: ='Пшеница мягкая 28 сен'!#REF! -> #REF!
A34: ='Пшеница мягкая 28 сен'!#REF! -> #REF! | B34: =IF('Пшеница мягкая 28 сен'!#REF!="","",'Пшеница мягкая 28 сен'!#REF!-'Пшеница мягкая 28 сен'!#REF!) -> #REF! | C34: ='Пшеница мягкая 28 сен'!#REF! -> #REF! | D34: =IF('Пшеница мягкая 28 сен'!#REF!="","",'Пшеница мягкая 28 сен'!#REF!-'Пшеница мягкая 28 сен'!#REF!) -> #REF! | E34: ='Пшеница мягкая 28 сен'!#REF! -> #REF! | F34: =IF('Пшеница мягкая 28 сен'!#REF!=0,"",'Пшеница мягкая 28 сен'!#REF!-'Пшеница мягкая 28 сен'!#REF!) -> #REF! | G34: ='Пшеница мягкая 28 сен'!#REF! -> #REF! | H34: =IF('Пшеница мягкая 28 сен'!#REF!=0,"",'Пшеница мягкая 28 сен'!#REF!-'Пшеница мягкая 28 сен'!#REF!) -> #REF! | I34: ='Пшеница мягкая 28 сен'!#REF! -> #REF! | J34: =IF('Пшеница мягкая 28 сен'!#REF!=0,"",'Пшеница мягкая 28 сен'!#REF!-'Пшеница мягкая 28 сен'!#REF!) -> #REF! | K34: ='Пшеница мягкая 28 сен'!#REF! -> #REF! | L34: =IF('Пшеница мягкая 28 сен'!#REF!=0,"",'Пшеница мягкая 28 сен'!#REF!-'Пшеница мягкая 28 сен'!#REF!) -> #REF! | M34: ='Пшеница мягкая 28 сен'!#REF! -> #REF! | N34: =IF(OR('Пшеница мягкая 28 сен'!#REF!="",'Пшеница мягкая 28 сен'!#REF!=0),"",'Пшеница мягкая 28 сен'!#REF!-'Пшеница мягкая 28 сен'!#REF!) -> #REF! | O34: ='Пшеница мягкая 28 сен'!#REF! -> #REF!
A35: ='Пшеница мягкая 28 сен'!#REF! -> #REF! | B35: =IF('Пшеница мягкая 28 сен'!#REF!="","",'Пшеница мягкая 28 сен'!#REF!-'Пшеница мягкая 28 сен'!#REF!) -> #REF! | C35: ='Пшеница мягкая 28 сен'!#REF! -> #REF! | D35: =IF('Пшеница мягкая 28 сен'!#REF!="","",'Пшеница мягкая 28 сен'!#REF!-'Пшеница мягкая 28 сен'!#REF!) -> #REF! | E35: ='Пшеница мягкая 28 сен'!#REF! -> #REF! | F35: =IF('Пшеница мягкая 28 сен'!#REF!=0,"",'Пшеница мягкая 28 сен'!#REF!-'Пшеница мягкая 28 сен'!#REF!) -> #REF! | G35: ='Пшеница мягкая 28 сен'!#REF! -> #REF! | H35: =IF('Пшеница мягкая 28 сен'!#REF!=0,"",'Пшеница мягкая 28 сен'!#REF!-'Пшеница мягкая 28 сен'!#REF!) -> #REF! | I35: ='Пшеница мягкая 28 сен'!#REF! -> #REF! | J35: =IF('Пшеница мягкая 28 сен'!#REF!=0,"",'Пшеница мягкая 28 сен'!#REF!-'Пшеница мягкая 28 сен'!#REF!) -> #REF! | K35: ='Пшеница мягкая 28 сен'!#REF! -> #REF! | L35: =IF('Пшеница мягкая 28 сен'!#REF!=0,"",'Пшеница мягкая 28 сен'!#REF!-'Пшеница мягкая 28 сен'!#REF!) -> #REF! | M35: ='Пшеница мягкая 28 сен'!#REF! -> #REF! | N35: =IF(OR('Пшеница мягкая 28 сен'!#REF!="",'Пшеница мягкая 28 сен'!#REF!=0),"",'Пшеница мягкая 28 сен'!#REF!-'Пшеница мягкая 28 сен'!#REF!) -> #REF! | O35: ='Пшеница мягкая 28 сен'!#REF! -> #REF!
A36: ='Пшеница мягкая 28 сен'!#REF! -> #REF! | B36: =IF('Пшеница мягкая 28 сен'!#REF!="","",'Пшеница мягкая 28 сен'!#REF!-'Пшеница мягкая 28 сен'!#REF!) -> #REF! | C36: ='Пшеница мягкая 28 сен'!#REF! -> #REF! | D36: =IF('Пшеница мягкая 28 сен'!#REF!="","",'Пшеница мягкая 28 сен'!#REF!-'Пшеница мягкая 28 сен'!#REF!) -> #REF! | E36: ='Пшеница мягкая 28 сен'!#REF! -> #REF! | F36: =IF('Пшеница мягкая 28 сен'!#REF!=0,"",'Пшеница мягкая 28 сен'!#REF!-'Пшеница мягкая 28 сен'!#REF!) -> #REF! | G36: ='Пшеница мягкая 28 сен'!#REF! -> #REF! | H36: =IF('Пшеница мягкая 28 сен'!#REF!=0,"",'Пшеница мягкая 28 сен'!#REF!-'Пшеница мягкая 28 сен'!#REF!) -> #REF! | I36: ='Пшеница мягкая 28 сен'!#REF! -> #REF! | J36: =IF('Пшеница мягкая 28 сен'!#REF!=0,"",'Пшеница мягкая 28 сен'!#REF!-'Пшеница мягкая 28 сен'!#REF!) -> #REF! | K36: ='Пшеница мягкая 28 сен'!#REF! -> #REF! | L36: =IF('Пшеница мягкая 28 сен'!#REF!=0,"",'Пшеница мягкая 28 сен'!#REF!-'Пшеница мягкая 28 сен'!#REF!) -> #REF! | M36: ='Пшеница мягкая 28 сен'!#REF! -> #REF! | N36: =IF(OR('Пшеница мягкая 28 сен'!#REF!="",'Пшеница мягкая 28 сен'!#REF!=0),"",'Пшеница мягкая 28 сен'!#REF!-'Пшеница мягкая 28 сен'!#REF!) -> #REF! | O36: ='Пшеница мягкая 28 сен'!#REF! -> #REF!
A37: ='Пшеница мягкая 28 сен'!#REF! -> #REF! | B37: =IF('Пшеница мягкая 28 сен'!#REF!="","",'Пшеница мягкая 28 сен'!#REF!-'Пшеница мягкая 28 сен'!#REF!) -> #REF! | C37: ='Пшеница мягкая 28 сен'!#REF! -> #REF! | D37: =IF('Пшеница мягкая 28 сен'!#REF!="","",'Пшеница мягкая 28 сен'!#REF!-'Пшеница мягкая 28 сен'!#REF!) -> #REF! | E37: ='Пшеница мягкая 28 сен'!#REF! -> #REF! | F37: =IF('Пшеница мягкая 28 сен'!#REF!=0,"",'Пшеница мягкая 28 сен'!#REF!-'Пшеница мягкая 28 сен'!#REF!) -> #REF! | G37: ='Пшеница мягкая 28 сен'!#REF! -> #REF! | H37: =IF('Пшеница мягкая 28 сен'!#REF!=0,"",'Пшеница мягкая 28 сен'!#REF!-'Пшеница мягкая 28 сен'!#REF!) -> #REF! | I37: ='Пшеница мягкая 28 сен'!#REF! -> #REF! | J37: =IF('Пшеница мягкая 28 сен'!#REF!=0,"",'Пшеница мягкая 28 сен'!#REF!-'Пшеница мягкая 28 сен'!#REF!) -> #REF! | K37: ='Пшеница мягкая 28 сен'!#REF! -> #REF! | L37: =IF('Пшеница мягкая 28 сен'!#REF!=0,"",'Пшеница мягкая 28 сен'!#REF!-'Пшеница мягкая 28 сен'!#REF!) -> #REF! | M37: ='Пшеница мягкая 28 сен'!#REF! -> #REF! | N37: =IF(OR('Пшеница мягкая 28 сен'!#REF!="",'Пшеница мягкая 28 сен'!#REF!=0),"",'Пшеница мягкая 28 сен'!#REF!-'Пшеница мягкая 28 сен'!#REF!) -> #REF! | O37: ='Пшеница мягкая 28 сен'!#REF! -> #REF!
A38: ='Пшеница мягкая 28 сен'!#REF! -> #REF! | B38: =IF('Пшеница мягкая 28 сен'!#REF!="","",'Пшеница мягкая 28 сен'!#REF!-'Пшеница мягкая 28 сен'!#REF!) -> #REF! | C38: ='Пшеница мягкая 28 сен'!#REF! -> #REF! | D38: =IF('Пшеница мягкая 28 сен'!#REF!="","",'Пшеница мягкая 28 сен'!#REF!-'Пшеница мягкая 28 сен'!#REF!) -> #REF! | E38: ='Пшеница мягкая 28 сен'!#REF! -> #REF! | F38: =IF('Пшеница мягкая 28 сен'!#REF!=0,"",'Пшеница мягкая 28 сен'!#REF!-'Пшеница мягкая 28 сен'!#REF!) -> #REF! | G38: ='Пшеница мягкая 28 сен'!#REF! -> #REF! | H38: =IF('Пшеница мягкая 28 сен'!#REF!="","",'Пшеница мягкая 28 сен'!#REF!-'Пшеница мягкая 28 сен'!#REF!) -> #REF! | I38: ='Пшеница мягкая 28 сен'!#REF! -> #REF! | J38: =IF('Пшеница мягкая 28 сен'!#REF!=0,"",'Пшеница мягкая 28 сен'!#REF!-'Пшеница мягкая 28 сен'!#REF!) -> #REF! | K38: ='Пшеница мягкая 28 сен'!#REF! -> #REF! | L38: =IF('Пшеница мягкая 28 сен'!#REF!="","",'Пшеница мягкая 28 сен'!#REF!-'Пшеница мягкая 28 сен'!#REF!) -> #REF! | M38: ='Пшеница мягкая 28 сен'!#REF! -> #REF! | N38: =IF(OR('Пшеница мягкая 28 сен'!#REF!="",'Пшеница мягкая 28 сен'!#REF!=0),"",'Пшеница мягкая 28 сен'!#REF!-'Пшеница мягкая 28 сен'!#REF!) -> #REF! | O38: ='Пшеница мягкая 28 сен'!#REF! -> #REF!
A39: ='Пшеница мягкая 28 сен'!#REF! -> #REF! | B39: =IF('Пшеница мягкая 28 сен'!#REF!="","",'Пшеница мягкая 28 сен'!#REF!-'Пшеница мягкая 28 сен'!#REF!) -> #REF! | C39: ='Пшеница мягкая 28 сен'!#REF! -> #REF! | D39: =IF('Пшеница мягкая 28 сен'!#REF!="","",'Пшеница мягкая 28 сен'!#REF!-'Пшеница мягкая 28 сен'!#REF!) -> #REF! | E39: ='Пшеница мягкая 28 сен'!#REF! -> #REF! | F39: =IF('Пшеница мягкая 28 сен'!#REF!=0,"",'Пшеница мягкая 28 сен'!#REF!-'Пшеница мягкая 28 сен'!#REF!) -> #REF! | G39: ='Пшеница мягкая 28 сен'!#REF! -> #REF! | H39: =IF('Пшеница мягкая 28 сен'!#REF!="","",'Пшеница мягкая 28 сен'!#REF!-'Пшеница мягкая 28 сен'!#REF!) -> #REF! | I39: ='Пшеница мягкая 28 сен'!#REF! -> #REF! | J39: =IF('Пшеница мягкая 28 сен'!#REF!=0,"",'Пшеница мягкая 28 сен'!#REF!-'Пшеница мягкая 28 сен'!#REF!) -> #REF! | K39: ='Пшеница мягкая 28 сен'!#REF! -> #REF! | L39: =IF('Пшеница мягкая 28 сен'!#REF!="","",'Пшеница мягкая 28 сен'!#REF!-'Пшеница мягкая 28 сен'!#REF!) -> #REF! | M39: ='Пшеница мягкая 28 сен'!#REF! -> #REF! | N39: =IF(OR('Пшеница мягкая 28 сен'!#REF!="",'Пшеница мягкая 28 сен'!#REF!=0),"",'Пшеница мягкая 28 сен'!#REF!-'Пшеница мягкая 28 сен'!#REF!) -> #REF! | O39: ='Пшеница мягкая 28 сен'!#REF! -> #REF!
A40: ='Пшеница мягкая 28 сен'!#REF! -> #REF! | B40: =IF('Пшеница мягкая 28 сен'!#REF!="","",'Пшеница мягкая 28 сен'!#REF!-'Пшеница мягкая 28 сен'!#REF!) -> #REF! | C40: ='Пшеница мягкая 28 сен'!#REF! -> #REF! | D40: =IF('Пшеница мягкая 28 сен'!#REF!="","",'Пшеница мягкая 28 сен'!#REF!-'Пшеница мягкая 28 сен'!#REF!) -> #REF! | E40: ='Пшеница мягкая 28 сен'!#REF! -> #REF! | F40: =IF('Пшеница мягкая 28 сен'!#REF!=0,"",'Пшеница мягкая 28 сен'!#REF!-'Пшеница мягкая 28 сен'!#REF!) -> #REF! | G40: ='Пшеница мягкая 28 сен'!#REF! -> #REF! | H40: =IF('Пшеница мягкая 28 сен'!#REF!=0,"",'Пшеница мягкая 28 сен'!#REF!-'Пшеница мягкая 28 сен'!#REF!) -> #REF! | I40: ='Пшеница мягкая 28 сен'!#REF! -> #REF! | J40: =IF('Пшеница мягкая 28 сен'!#REF!=0,"",'Пшеница мягкая 28 сен'!#REF!-'Пшеница мягкая 28 сен'!#REF!) -> #REF! | K40: ='Пшеница мягкая 28 сен'!#REF! -> #REF! | L40: =IF('Пшеница мягкая 28 сен'!#REF!=0,"",'Пшеница мягкая 28 сен'!#REF!-'Пшеница мягкая 28 сен'!#REF!) -> #REF! | M40: ='Пшеница мягкая 28 сен'!#REF! -> #REF! | N40: =IF(OR('Пшеница мягкая 28 сен'!#REF!="",'Пшеница мягкая 28 сен'!#REF!=0),"",'Пшеница мягкая 28 сен'!#REF!-'Пшеница мягкая 28 сен'!#REF!) -> #REF! | O40: ='Пшеница мягкая 28 сен'!#REF! -> #REF!
A41: ='Пшеница мягкая 28 сен'!#REF! -> #REF! | B41: =IF('Пшеница мягкая 28 сен'!#REF!="","",'Пшеница мягкая 28 сен'!#REF!-'Пшеница мягкая 28 сен'!#REF!) -> #REF! | C41: ='Пшеница мягкая 28 сен'!#REF! -> #REF! | D41: =IF('Пшеница мягкая 28 сен'!#REF!="","",'Пшеница мягкая 28 сен'!#REF!-'Пшеница мягкая 28 сен'!#REF!) -> #REF! | E41: ='Пшеница мягкая 28 сен'!#REF! -> #REF! | F41: =IF('Пшеница мягкая 28 сен'!#REF!=0,"",'Пшеница мягкая 28 сен'!#REF!-'Пшеница мягкая 28 сен'!#REF!) -> #REF! | G41: ='Пшеница мягкая 28 сен'!#REF! -> #REF! | H41: =IF('Пшеница мягкая 28 сен'!#REF!=0,"",'Пшеница мягкая 28 сен'!#REF!-'Пшеница мягкая 28 сен'!#REF!) -> #REF! | I41: ='Пшеница мягкая 28 сен'!#REF! -> #REF! | J41: =IF('Пшеница мягкая 28 сен'!#REF!=0,"",'Пшеница мягкая 28 сен'!#REF!-'Пшеница мягкая 28 сен'!#REF!) -> #REF! | K41: ='Пшеница мягкая 28 сен'!#REF! -> #REF! | L41: =IF('Пшеница мягкая 28 сен'!#REF!=0,"",'Пшеница мягкая 28 сен'!#REF!-'Пшеница мягкая 28 сен'!#REF!) -> #REF! | M41: ='Пшеница мягкая 28 сен'!#REF! -> #REF! | N41: =IF(OR('Пшеница мягкая 28 сен'!#REF!="",'Пшеница мягкая 28 сен'!#REF!=0),"",'Пшеница мягкая 28 сен'!#REF!-'Пшеница мягкая 28 сен'!#REF!) -> #REF! | O41: ='Пшеница мягкая 28 сен'!#REF! -> #REF!
...
